[2025-01-30T19:13:41.912+0000] {local_task_job_runner.py:123} INFO - ::group::Pre task execution logs
[2025-01-30T19:13:41.919+0000] {taskinstance.py:2613} INFO - Dependencies all met for dep_context=non-requeueable deps ti=<TaskInstance: etl_dag.refine_books manual__2025-01-30T12:13:05-07:00 [queued]>
[2025-01-30T19:13:41.923+0000] {taskinstance.py:2613} INFO - Dependencies all met for dep_context=requeueable deps ti=<TaskInstance: etl_dag.refine_books manual__2025-01-30T12:13:05-07:00 [queued]>
[2025-01-30T19:13:41.923+0000] {taskinstance.py:2866} INFO - Starting attempt 1 of 1
[2025-01-30T19:13:41.928+0000] {taskinstance.py:2889} INFO - Executing <Task(BashOperator): refine_books> on 2025-01-30 19:13:05+00:00
[2025-01-30T19:13:41.932+0000] {standard_task_runner.py:72} INFO - Started process 267 to run task
[2025-01-30T19:13:41.936+0000] {standard_task_runner.py:104} INFO - Running: ['***', 'tasks', 'run', 'etl_dag', 'refine_books', 'manual__2025-01-30T12:13:05-07:00', '--job-id', '64', '--raw', '--subdir', 'DAGS_FOLDER/my_first_dag.py', '--cfg-path', '/tmp/tmpok6xw5tr']
[2025-01-30T19:13:41.937+0000] {standard_task_runner.py:105} INFO - Job 64: Subtask refine_books
[2025-01-30T19:13:41.960+0000] {task_command.py:467} INFO - Running <TaskInstance: etl_dag.refine_books manual__2025-01-30T12:13:05-07:00 [running]> on host 48308722451a
[2025-01-30T19:13:41.995+0000] {taskinstance.py:3132} INFO - Exporting env vars: AIRFLOW_CTX_DAG_OWNER='***' AIRFLOW_CTX_DAG_ID='etl_dag' AIRFLOW_CTX_TASK_ID='refine_books' AIRFLOW_CTX_EXECUTION_DATE='2025-01-30T19:13:05+00:00' AIRFLOW_CTX_TRY_NUMBER='1' AIRFLOW_CTX_DAG_RUN_ID='manual__2025-01-30T12:13:05-07:00'
[2025-01-30T19:13:41.996+0000] {taskinstance.py:731} INFO - ::endgroup::
[2025-01-30T19:13:42.001+0000] {subprocess.py:78} INFO - Tmp dir root location: /tmp
[2025-01-30T19:13:42.002+0000] {subprocess.py:88} INFO - Running command: ['/usr/bin/bash', '-c', 'python3 /opt/***/data_collection/treat_books.py --data_lake_path $DATA_LAKE_PATH']
[2025-01-30T19:13:42.005+0000] {subprocess.py:99} INFO - Output:
[2025-01-30T19:13:42.402+0000] {subprocess.py:106} INFO - No item
[2025-01-30T19:13:42.403+0000] {subprocess.py:106} INFO - /opt/***/data_lake/refined/parquet/books
[2025-01-30T19:13:42.403+0000] {subprocess.py:106} INFO - Traceback (most recent call last):
[2025-01-30T19:13:42.403+0000] {subprocess.py:106} INFO -   File "/home/***/.local/lib/python3.11/site-packages/pandas/core/indexes/base.py", line 3652, in get_loc
[2025-01-30T19:13:42.404+0000] {subprocess.py:106} INFO -     return self._engine.get_loc(casted_key)
[2025-01-30T19:13:42.404+0000] {subprocess.py:106} INFO -            ^^^^^^^^^^^^^^^^^^^^^^^^^^^^^^^^
[2025-01-30T19:13:42.404+0000] {subprocess.py:106} INFO -   File "pandas/_libs/index.pyx", line 147, in pandas._libs.index.IndexEngine.get_loc
[2025-01-30T19:13:42.404+0000] {subprocess.py:106} INFO -   File "pandas/_libs/index.pyx", line 176, in pandas._libs.index.IndexEngine.get_loc
[2025-01-30T19:13:42.405+0000] {subprocess.py:106} INFO -   File "pandas/_libs/hashtable_class_helper.pxi", line 7080, in pandas._libs.hashtable.PyObjectHashTable.get_item
[2025-01-30T19:13:42.405+0000] {subprocess.py:106} INFO -   File "pandas/_libs/hashtable_class_helper.pxi", line 7088, in pandas._libs.hashtable.PyObjectHashTable.get_item
[2025-01-30T19:13:42.405+0000] {subprocess.py:106} INFO - KeyError: 'date'
[2025-01-30T19:13:42.405+0000] {subprocess.py:106} INFO - 
[2025-01-30T19:13:42.405+0000] {subprocess.py:106} INFO - The above exception was the direct cause of the following exception:
[2025-01-30T19:13:42.405+0000] {subprocess.py:106} INFO - 
[2025-01-30T19:13:42.406+0000] {subprocess.py:106} INFO - Traceback (most recent call last):
[2025-01-30T19:13:42.406+0000] {subprocess.py:106} INFO -   File "/opt/***/data_collection/treat_books.py", line 60, in <module>
[2025-01-30T19:13:42.406+0000] {subprocess.py:106} INFO -     save_data(data, filename, zone="refined", context="books", file_type="parquet")
[2025-01-30T19:13:42.406+0000] {subprocess.py:106} INFO -   File "/opt/***/data_collection/utils.py", line 38, in save_data
[2025-01-30T19:13:42.406+0000] {subprocess.py:106} INFO -     df['date'] = pd.to_numeric(df['date'], errors='coerce').astype('Int64')
[2025-01-30T19:13:42.406+0000] {subprocess.py:106} INFO -                                ~~^^^^^^^^
[2025-01-30T19:13:42.407+0000] {subprocess.py:106} INFO -   File "/home/***/.local/lib/python3.11/site-packages/pandas/core/frame.py", line 3760, in __getitem__
[2025-01-30T19:13:42.407+0000] {subprocess.py:106} INFO -     indexer = self.columns.get_loc(key)
[2025-01-30T19:13:42.407+0000] {subprocess.py:106} INFO -               ^^^^^^^^^^^^^^^^^^^^^^^^^
[2025-01-30T19:13:42.407+0000] {subprocess.py:106} INFO -   File "/home/***/.local/lib/python3.11/site-packages/pandas/core/indexes/base.py", line 3654, in get_loc
[2025-01-30T19:13:42.407+0000] {subprocess.py:106} INFO -     raise KeyError(key) from err
[2025-01-30T19:13:42.407+0000] {subprocess.py:106} INFO - KeyError: 'date'
[2025-01-30T19:13:42.437+0000] {subprocess.py:110} INFO - Command exited with return code 1
[2025-01-30T19:13:42.443+0000] {taskinstance.py:3311} ERROR - Task failed with exception
Traceback (most recent call last):
  File "/home/airflow/.local/lib/python3.11/site-packages/airflow/models/taskinstance.py", line 767, in _execute_task
    result = _execute_callable(context=context, **execute_callable_kwargs)
             ^^^^^^^^^^^^^^^^^^^^^^^^^^^^^^^^^^^^^^^^^^^^^^^^^^^^^^^^^^^^^
  File "/home/airflow/.local/lib/python3.11/site-packages/airflow/models/taskinstance.py", line 733, in _execute_callable
    return ExecutionCallableRunner(
           ^^^^^^^^^^^^^^^^^^^^^^^^
  File "/home/airflow/.local/lib/python3.11/site-packages/airflow/utils/operator_helpers.py", line 252, in run
    return self.func(*args, **kwargs)
           ^^^^^^^^^^^^^^^^^^^^^^^^^^
  File "/home/airflow/.local/lib/python3.11/site-packages/airflow/models/baseoperator.py", line 422, in wrapper
    return func(self, *args, **kwargs)
           ^^^^^^^^^^^^^^^^^^^^^^^^^^^
  File "/home/airflow/.local/lib/python3.11/site-packages/airflow/operators/bash.py", line 276, in execute
    raise AirflowException(
airflow.exceptions.AirflowException: Bash command failed. The command returned a non-zero exit code 1.
[2025-01-30T19:13:42.446+0000] {taskinstance.py:1225} INFO - Marking task as FAILED. dag_id=etl_dag, task_id=refine_books, run_id=manual__2025-01-30T12:13:05-07:00, execution_date=20250130T191305, start_date=20250130T191341, end_date=20250130T191342
[2025-01-30T19:13:42.453+0000] {taskinstance.py:340} INFO - ::group::Post task execution logs
[2025-01-30T19:13:42.453+0000] {standard_task_runner.py:124} ERROR - Failed to execute job 64 for task refine_books (Bash command failed. The command returned a non-zero exit code 1.; 267)
Traceback (most recent call last):
  File "/home/airflow/.local/lib/python3.11/site-packages/airflow/task/task_runner/standard_task_runner.py", line 117, in _start_by_fork
    ret = args.func(args, dag=self.dag)
          ^^^^^^^^^^^^^^^^^^^^^^^^^^^^^
  File "/home/airflow/.local/lib/python3.11/site-packages/airflow/cli/cli_config.py", line 49, in command
    return func(*args, **kwargs)
           ^^^^^^^^^^^^^^^^^^^^^
  File "/home/airflow/.local/lib/python3.11/site-packages/airflow/utils/cli.py", line 116, in wrapper
    return f(*args, **kwargs)
           ^^^^^^^^^^^^^^^^^^
  File "/home/airflow/.local/lib/python3.11/site-packages/airflow/cli/commands/task_command.py", line 483, in task_run
    task_return_code = _run_task_by_selected_method(args, _dag, ti)
                       ^^^^^^^^^^^^^^^^^^^^^^^^^^^^^^^^^^^^^^^^^^^^
  File "/home/airflow/.local/lib/python3.11/site-packages/airflow/cli/commands/task_command.py", line 256, in _run_task_by_selected_method
    return _run_raw_task(args, ti)
           ^^^^^^^^^^^^^^^^^^^^^^^
  File "/home/airflow/.local/lib/python3.11/site-packages/airflow/cli/commands/task_command.py", line 341, in _run_raw_task
    return ti._run_raw_task(
           ^^^^^^^^^^^^^^^^^
  File "/home/airflow/.local/lib/python3.11/site-packages/airflow/utils/session.py", line 97, in wrapper
    return func(*args, session=session, **kwargs)
           ^^^^^^^^^^^^^^^^^^^^^^^^^^^^^^^^^^^^^^
  File "/home/airflow/.local/lib/python3.11/site-packages/airflow/models/taskinstance.py", line 3005, in _run_raw_task
    return _run_raw_task(
           ^^^^^^^^^^^^^^
  File "/home/airflow/.local/lib/python3.11/site-packages/airflow/models/taskinstance.py", line 273, in _run_raw_task
    TaskInstance._execute_task_with_callbacks(
  File "/home/airflow/.local/lib/python3.11/site-packages/airflow/models/taskinstance.py", line 3159, in _execute_task_with_callbacks
    result = self._execute_task(context, task_orig)
             ^^^^^^^^^^^^^^^^^^^^^^^^^^^^^^^^^^^^^^
  File "/home/airflow/.local/lib/python3.11/site-packages/airflow/models/taskinstance.py", line 3183, in _execute_task
    return _execute_task(self, context, task_orig)
           ^^^^^^^^^^^^^^^^^^^^^^^^^^^^^^^^^^^^^^^
  File "/home/airflow/.local/lib/python3.11/site-packages/airflow/models/taskinstance.py", line 767, in _execute_task
    result = _execute_callable(context=context, **execute_callable_kwargs)
             ^^^^^^^^^^^^^^^^^^^^^^^^^^^^^^^^^^^^^^^^^^^^^^^^^^^^^^^^^^^^^
  File "/home/airflow/.local/lib/python3.11/site-packages/airflow/models/taskinstance.py", line 733, in _execute_callable
    return ExecutionCallableRunner(
           ^^^^^^^^^^^^^^^^^^^^^^^^
  File "/home/airflow/.local/lib/python3.11/site-packages/airflow/utils/operator_helpers.py", line 252, in run
    return self.func(*args, **kwargs)
           ^^^^^^^^^^^^^^^^^^^^^^^^^^
  File "/home/airflow/.local/lib/python3.11/site-packages/airflow/models/baseoperator.py", line 422, in wrapper
    return func(self, *args, **kwargs)
           ^^^^^^^^^^^^^^^^^^^^^^^^^^^
  File "/home/airflow/.local/lib/python3.11/site-packages/airflow/operators/bash.py", line 276, in execute
    raise AirflowException(
airflow.exceptions.AirflowException: Bash command failed. The command returned a non-zero exit code 1.
[2025-01-30T19:13:42.489+0000] {local_task_job_runner.py:266} INFO - Task exited with return code 1
[2025-01-30T19:13:42.498+0000] {taskinstance.py:3895} INFO - 0 downstream tasks scheduled from follow-on schedule check
[2025-01-30T19:13:42.498+0000] {local_task_job_runner.py:245} INFO - ::endgroup::
